<?xml version="1.0" encoding="utf-8"?>
<!-- This URDF was automatically created by SolidWorks to URDF Exporter! Originally created by Stephen Brawner (brawner@gmail.com) 
     Commit Version: 1.6.0-4-g7f85cfe  Build Version: 1.6.7995.38578
     For more information, please see http://wiki.ros.org/sw_urdf_exporter -->
<robot
  name="kelambite">
  <link
    name="base_link">
    <inertial>
      <origin
        xyz="-1.7843299608045E-05 3.46944695195361E-18 -0.00505111739670027"
        rpy="0 0 0" />
      <mass
        value="0.0122513274122872" />
      <inertia
        ixx="1.07927243404358E-06"
        ixy="4.40840680380612E-22"
        ixz="-5.33541774147311E-10"
        iyy="1.75383410028849E-06"
        iyz="-8.47430588760128E-24"
        izz="2.62954690382201E-06" />
    </inertial>
    <visual>
      <origin
        xyz="0 0 0"
        rpy="0 0 0" />
      <geometry>
        <mesh
          filename="package://kelambite/meshes/base_link.STL" />
      </geometry>
      <material
        name="">
        <color
          rgba="0.792156862745098 0.819607843137255 0.933333333333333 1" />
      </material>
    </visual>
    <collision>
      <origin
        xyz="0 0 0"
        rpy="0 0 0" />
      <geometry>
        <mesh
          filename="package://kelambite/meshes/base_link.STL" />
      </geometry>
    </collision>
  </link>
  <link
    name="LF_wheel">
    <inertial>
      <origin
        xyz="-8.67361737988404E-19 1.73472347597681E-18 -0.00296938775510204"
        rpy="0 0 0" />
      <mass
        value="0.0018472564803108" />
      <inertia
        ixx="5.262622905127E-08"
        ixy="4.19309484730494E-24"
        ixz="1.08890008202177E-23"
        iyy="5.262622905127E-08"
        iyz="-4.84242346075222E-27"
        izz="9.41723813840077E-08" />
    </inertial>
    <visual>
      <origin
        xyz="0 0 0"
        rpy="0 0 0" />
      <geometry>
        <mesh
          filename="package://kelambite/meshes/LF_wheel.STL" />
      </geometry>
      <material
        name="">
        <color
          rgba="0.792156862745098 0.819607843137255 0.933333333333333 1" />
      </material>
    </visual>
    <collision>
      <origin
        xyz="0 0 0"
        rpy="0 0 0" />
      <geometry>
        <mesh
          filename="package://kelambite/meshes/LF_wheel.STL" />
      </geometry>
    </collision>
  </link>
  <joint
    name="left_front_wheel"
    type="continuous">
    <origin
      xyz="0.013461 0.023 -0.0074918"
      rpy="-1.5708 0 0" />
    <parent
      link="base_link" />
    <child
      link="LF_wheel" />
    <axis
      xyz="0 0 1" />
    <limit
      effort="10"
      velocity="10" />
    <dynamics
      damping="0.1"
      friction="0.1" />
  </joint>
  <link
    name="LB_wheel">
    <inertial>
      <origin
        xyz="-3.46944695195361E-18 0 -0.00296938775510204"
        rpy="0 0 0" />
      <mass
        value="0.0018472564803108" />
      <inertia
        ixx="5.262622905127E-08"
        ixy="-7.66060979597263E-42"
        ixz="6.52280154631335E-25"
        iyy="5.26262290512699E-08"
        iyz="1.13705391011133E-40"
        izz="9.41723813840076E-08" />
    </inertial>
    <visual>
      <origin
        xyz="0 0 0"
        rpy="0 0 0" />
      <geometry>
        <mesh
          filename="package://kelambite/meshes/LB_wheel.STL" />
      </geometry>
      <material
        name="">
        <color
          rgba="0.792156862745098 0.819607843137255 0.933333333333333 1" />
      </material>
    </visual>
    <collision>
      <origin
        xyz="0 0 0"
        rpy="0 0 0" />
      <geometry>
        <mesh
          filename="package://kelambite/meshes/LB_wheel.STL" />
      </geometry>
    </collision>
  </link>
  <joint
    name="left_back_wheel"
    type="continuous">
    <origin
      xyz="-0.015201 0.023 -0.0074918"
      rpy="-1.5708 0 0" />
    <parent
      link="base_link" />
    <child
      link="LB_wheel" />
    <axis
      xyz="0 0 1" />
    <limit
      effort="10"
      velocity="10" />
    <dynamics
      damping="0.1"
      friction="0.1" />
  </joint>
  <link
    name="RF_wheel">
    <inertial>
      <origin
        xyz="1.73472347597681E-18 0 0.00296938775510204"
        rpy="0 0 0" />
      <mass
        value="0.0018472564803108" />
      <inertia
        ixx="5.262622905127E-08"
        ixy="1.0132659581187E-24"
        ixz="-3.69606293567246E-26"
        iyy="5.262622905127E-08"
        iyz="-3.42049535484682E-27"
        izz="9.41723813840077E-08" />
    </inertial>
    <visual>
      <origin
        xyz="0 0 0"
        rpy="0 0 0" />
      <geometry>
        <mesh
          filename="package://kelambite/meshes/RF_wheel.STL" />
      </geometry>
      <material
        name="">
        <color
          rgba="0.792156862745098 0.819607843137255 0.933333333333333 1" />
      </material>
    </visual>
    <collision>
      <origin
        xyz="0 0 0"
        rpy="0 0 0" />
      <geometry>
        <mesh
          filename="package://kelambite/meshes/RF_wheel.STL" />
      </geometry>
    </collision>
  </link>
  <joint
    name="right_front1111-wheel"
    type="continuous">
    <origin
      xyz="0.013461 -0.023 -0.0074918"
      rpy="-1.5708 0 0" />
    <parent
      link="base_link" />
    <child
      link="RF_wheel" />
    <axis
      xyz="0 0 -1" />
    <limit
      effort="10"
      velocity="10" />
    <dynamics
      damping="0.1"
      friction="0.1" />
  </joint>
  <link
    name="RB_wheel">
    <inertial>
      <origin
        xyz="0 0 0.00296938775510204"
        rpy="0 0 0" />
      <mass
        value="0.0018472564803108" />
      <inertia
        ixx="5.262622905127E-08"
        ixy="9.30547896863396E-25"
        ixz="-2.92995444779018E-26"
        iyy="5.262622905127E-08"
        iyz="7.07119343498405E-27"
        izz="9.41723813840077E-08" />
    </inertial>
    <visual>
      <origin
        xyz="0 0 0"
        rpy="0 0 0" />
      <geometry>
        <mesh
          filename="package://kelambite/meshes/RB_wheel.STL" />
      </geometry>
      <material
        name="">
        <color
          rgba="0.792156862745098 0.819607843137255 0.933333333333333 1" />
      </material>
    </visual>
    <collision>
      <origin
        xyz="0 0 0"
        rpy="0 0 0" />
      <geometry>
        <mesh
          filename="package://kelambite/meshes/RB_wheel.STL" />
      </geometry>
    </collision>
  </link>
  <joint
    name="right_back_wheel"
    type="continuous">
    <origin
      xyz="-0.015201 -0.023 -0.0074918"
      rpy="-1.5708 0 0" />
    <parent
      link="base_link" />
    <child
      link="RB_wheel" />
    <axis
      xyz="0 0 -1" />
    <limit
      effort="10"
      velocity="10" />
    <dynamics
      damping="0.1"
      friction="0.1" />
  </joint>
</robot>